Workbook

Sheet FCE calculation
B2: From DairyNZ statistics
B3: Location | C3: Season | D3: Cow numbers | E3: Effective area (ha) | F3: Stocking rate (cows/ha) | G3: Total Milksolids (kg) | H3: MS/cow | I3: MS/ha | J3: Liveweight | K3: Feed demand/ cow (total kg) | L3: Feed demand/ ha (total kg) | M3: Feed demand (total kg) | N3: Feed demand (total kg) | O3: FCE (kg DM/ kg MS) | P3: FCE (MJ ME/ kg MS)
B5: Ref DairyNZ production statistics for North Canterbury + Dairybase data for feed demand - based on MPI method from
B6: Milking cow
B7: North Canterbury | C7: ='FCE calculation Original'!C6 -> 2022-23 | D7: 697292 | E7: 200849 | F7: =D7/E7 -> 3.4717225 | G7: 301907445 | H7: 434 | I7: 1503 | J7: 482 | K7: ='Dairybase (North Cant) stats'!AR3*1000 -> 4574.9701 | L7: =('Dairybase (North Cant) stats'!AF3+'Dairybase (North Cant) stats'!AG3+'Dairybase (North Cant) stats'!AH3)*1000 -> 15883.027 | M7: =D7*K7 -> 3.1900901e+09 | N7: =E7*L7 -> 3.1900901e+09 | O7: =M7/G7 -> 10.56645 | P7: =O7*$C$13 -> 116.23095
B8: North Canterbury | C8: ='FCE calculation Original'!C7 -> 2021-22 | D8: 720520 | E8: 206707 | F8: =D8/E8 -> 3.4857068 | G8: 302680670 | H8: 420 | I8: 1464 | J8: 486 | K8: ='Dairybase (North Cant) stats'!AR4*1000 -> 4671.717 | L8: =('Dairybase (North Cant) stats'!AF4+'Dairybase (North Cant) stats'!AG4+'Dairybase (North Cant) stats'!AH4)*1000 -> 16284.236 | M8: =D8*K8 -> 3.3660656e+09 | N8: =E8*L8 -> 3.3660656e+09 | O8: =M8/G8 -> 11.120847 | P8: =O8*$C$13 -> 122.32932
B9: North Canterbury | C9: ='FCE calculation Original'!C8 -> 2020-21 | D9: 723148 | E9: 207637 | F9: =D9/E9 -> 3.4827511 | G9: 315587803 | H9: 436 | I9: 1520 | J9: 458 | K9: ='Dairybase (North Cant) stats'!AR5*1000 -> 5062.0334 | L9: =('Dairybase (North Cant) stats'!AF5+'Dairybase (North Cant) stats'!AG5+'Dairybase (North Cant) stats'!AH5)*1000 -> 17629.803 | M9: =D9*K9 -> 3.6605994e+09 | N9: =E9*L9 -> 3.6605994e+09 | O9: =M9/G9 -> 11.599306 | P9: =O9*$C$13 -> 127.59236
B10: North Canterbury | C10: ='FCE calculation Original'!C9 -> 2019-20 | D10: 719289 | E10: 206790 | F10: =D10/E10 -> 3.4783549 | G10: 312626067 | H10: 435 | I10: 1512 | J10: 451 | K10: ='Dairybase (North Cant) stats'!AR6*1000 -> 5002.245 | L10: =('Dairybase (North Cant) stats'!AF6+'Dairybase (North Cant) stats'!AG6+'Dairybase (North Cant) stats'!AH6)*1000 -> 17399.583 | M10: =D10*K10 -> 3.5980598e+09 | N10: =E10*L10 -> 3.5980598e+09 | O10: =M10/G10 -> 11.509148 | P10: =O10*$C$13 -> 126.60063
B11: Average | F11: =AVERAGE(F7:F10) -> 3.4796338 | O11: =AVERAGE(O7:O10) -> 11.198938 | P11: =O11*$C$13 -> 123.18832
B13: MJ ME/ kgDM | C13: 11
B14: Repacement rate | C14: 0.22

Sheet Replacement + Dry Feed
B2: All at 11 MJ/ME per kg DM
B3: Replacements | C3: Age | G3: If split R1 & R2 stock classes use the below | I3: If classes combined use the below
B4: Liveweight | C4: Annual DM 3-10 months | D4: Annual DM 11-22 months | E4: Annual DM 3-22 months | G4: Daily DM/cow 3-10 months | H4: Daily DM/cow 11-22 months | I4: Daily DM/cow 3-22 months
B5: 425 | C5: 891 | D5: 2455 | E5: 3346 | G5: =C5/SUM($C$33:$C$39) -> 4.2028302 | H5: =D5/SUM($C$40:$C$44,$C$33:$C$39) -> 6.7260274 | I5: =E5/SUM($C$40:$C$44,$C$33:$C$39,$C$33:$C$39) -> 5.7989601
B6: 450 | C6: 953 | D6: 2535 | E6: 3488 | G6: =C6/SUM($C$33:$C$39) -> 4.495283 | H6: =D6/SUM($C$40:$C$44,$C$33:$C$39) -> 6.9452055 | I6: =E6/SUM($C$40:$C$44,$C$33:$C$39,$C$33:$C$39) -> 6.0450607
B7: 475 | C7: 996 | D7: 2707 | E7: 3703 | G7: =C7/SUM($C$33:$C$39) -> 4.6981132 | H7: =D7/SUM($C$40:$C$44,$C$33:$C$39) -> 7.4164384 | I7: =E7/SUM($C$40:$C$44,$C$33:$C$39,$C$33:$C$39) -> 6.4176776
B8: 500 | C8: 1011 | D8: 2727 | E8: 3738 | G8: =C8/SUM($C$33:$C$39) -> 4.7688679 | H8: =D8/SUM($C$40:$C$44,$C$33:$C$39) -> 7.4712329 | I8: =E8/SUM($C$40:$C$44,$C$33:$C$39,$C$33:$C$39) -> 6.4783362
B9: 525 | C9: 1048 | D9: 2839 | E9: 3887 | G9: =C9/SUM($C$33:$C$39) -> 4.9433962 | H9: =D9/SUM($C$40:$C$44,$C$33:$C$39) -> 7.7780822 | I9: =E9/SUM($C$40:$C$44,$C$33:$C$39,$C$33:$C$39) -> 6.7365685
B10: 550 | C10: 1117 | D10: 2995 | E10: 4112 | G10: =C10/SUM($C$33:$C$39) -> 5.2688679 | H10: =D10/SUM($C$40:$C$44,$C$33:$C$39) -> 8.2054795 | I10: =E10/SUM($C$40:$C$44,$C$33:$C$39,$C$33:$C$39) -> 7.1265165
G11: From December | H11: From August | I11: From December
B14: Application for Replacements
B15: Month | C15: August | D15: September | E15: October | F15: November | G15: December | H15: January | I15: February | J15: March | K15: April | L15: May | M15: June | N15: July
B16: Number Replacements (% Peak cow) | C16: 0.22 | D16: 0.22 | E16: 0.22 | F16: 0.22 | G16: 0.44 | H16: 0.44 | I16: 0.44 | J16: 0.44 | K16: 0.44 | L16: 0.44 | M16: 0.44 | N16: 0.44
B17: Feed Requirement | C17: =$I$7 -> 6.4176776 | D17: =$I$7 -> 6.4176776 | E17: =$I$7 -> 6.4176776 | F17: =$I$7 -> 6.4176776 | G17: =$I$7 -> 6.4176776 | H17: =$I$7 -> 6.4176776 | I17: =$I$7 -> 6.4176776 | J17: =$I$7 -> 6.4176776 | ... N17: =$I$7 -> 6.4176776
B20: Dry-cows | C20: Weeks pre-calving DM/day/cow
B21: Liveweight | C21: +12 | D21: 8 | E21: 4 | F21: 2
B22: 350 | C22: 5 | D22: 5.7 | E22: 6.8 | F22: 7.7
B23: 400 | C23: 5.5 | D23: 6.3 | E23: 7.6 | F23: 8.5
B24: 450 | C24: 6 | D24: 6.8 | E24: 8.3 | F24: 9.3
B25: 500 | C25: 6.5 | D25: 7.4 | E25: 9 | F25: 10.1
B26: 550 | C26: 7 | D26: 8 | E26: 9.6 | F26: 10.8
B28: Application for Dry Cows
B29: Month | C29: August | D29: September | E29: October | F29: November | G29: December | H29: January | I29: February | J29: March | K29: April | L29: May | M29: June | N29: July
B30: Feed Requirement | C30: 6 | D30: 6 | E30: 6 | F30: 6 | G30: 6 | H30: 6 | I30: 6 | J30: 6 | K30: 6 | L30: 6.8 | M30: 8.3 | N30: 9.3
C32: Days | D32: Replacement Month
B33: December | C33: 31 | D33: 4
B34: January | C34: 31 | D34: 5
B35: February | C35: 28 | D35: 6
B36: March | C36: 31 | D36: 7
B37: April | C37: 30 | D37: 8
B38: May | C38: 31 | D38: 9
B39: June | C39: 30 | D39: 10
B40: July | C40: 31 | D40: 11
B41: August | C41: 31 | D41: 12
B42: September | C42: 30 | D42: 1
B43: October | C43: 31 | D43: 2
B44: November | C44: 30 | D44: 3

Sheet Dairybase (North Cant) stats
B2: Season | C2: District Councils | D2: Business type | E2: Farm Count | F2: Operating Profit (EFS)/ha | G2: Non-dairy operating profit $ Per Ha | H2: TOTAL OPERATING PROFIT $ Per Ha | I2: Freight and general farm working expenses $/Kg MS | J2: Supplements made, purchased, cropped $/Kg MS | K2: Feed Inventory Adjustment $/Kg MS | L2: Calf Rearing (Excluding Labour) $/Kg MS | M2: Total Supplement Expenses $/Kg MS | N2: Net heifer/General grazing $/Kg MS | O2: Winter Cow Grazing $/Kg MS | P2: Net cost of leased runoff land $/Kg MS | Q2: Owned Run-off Adjustment $/Kg MS | R2: Total Grazing & Run Off Expenses $/Kg MS | S2: Total Feed Expenses $/Kg MS | T2: Supplements made, purchased and cropped (Per Ha) | U2: Feed Inventory Adjustment $ Per Ha | V2: Calf Rearing (Excluding Labour) $ Per Ha | W2: Total Supplement Expenses $ Per Ha | X2: Net heifer/General grazing $ Per Ha | Y2: Winter Cow Grazing $ Per Ha | Z2: Net cost of leased runoff land $ Per Ha | AA2: Owned Run-off Adjustment $ Per Ha | AB2: Total Grazing & Run Off Expenses $ Per Ha | AC2: Total Feed Expenses $ Per Ha | AD2: Pasture and Crop harvested 2020 (t DM/ha) | AE2: Feed (Pasture and crop) exported (t DM/ha) | AF2: Pasture and Crop eaten 2020 (t DM/ha) | AG2: Imported supplements eaten (purchased or imported from support block) (t DM/ha) | AH2: Supplements made on farm in previous seasons eaten (t/DM/ha) | AI2: Off-farm grazing - dry cow winter grazing (t DM/ha) | AJ2: Off-farm grazing - young stock (t DM/ha) | AK2: Total Feed Eaten 2020 (t DM/ha) | AL2: Imported supplements eaten 2020 (purchased + support block + feed inventory) (kg DM/cow) | AM2: Debt to Assets % | AN2: Total Return on Assets % (Dairy) | AO2: Return on Equity % | AP2: Total return on equity % | AQ2: North Canterbury Milking Cow Stocking Rate | AR2: Total Milking Cow Feed Eaten (t/DM/cow) | AS2: Milking Cow Pasture & Crop Eaten (t/DM/cow) | AT2: Milking Cow Supplements Eaten (t/DM/cow) | AU2: Milking Cow Supplement % | AV2: North Canterbury Replacement Stocking Rate | AW2: Total Replacement Feed Eaten (t/DM/cow) | AX2: North Canterbury Dry Cow Stocking Rate | AY2: Total Wintering Feed Eaten (t/DM/cow)
B3: 2022-23 | C3: Waimakariri, Selwyn, Hurunui & Ashburton | D3: Owner operator | E3: 28 | F3: 4076.3366 | G3: 16.223576 | H3: 4092.5602 | I3: 0.064691165 | J3: 1.0890769 | K3: 0.03004548 | L3: 0.067143532 | M3: 1.126175 | N3: 0.63950146 | O3: 0.13715001 | P3: 0.06541926 | Q3: 0.12869152 | R3: 0.97076226 | S3: 2.0969372 | T3: 1666.1337 | U3: 44.312287 | V3: 94.886936 | W3: 1716.7084 | Y3: 205.71551 | Z3: 80.110775 | AA3: 157.36909 | AB3: 1479.0342 | AC3: 3195.7426 | AD3: 13.806135 | AE3: 0.2849834 | AF3: 13.521152 | AG3: 2.1813086 | AH3: 0.18056663 | AI3: 2.2151641 | AJ3: 2.5931819 | AK3: 20.691373 | AL3: 667.80887 | AM3: 0.48709039 | AN3: 0.035189685 | AO3: 0.092947998 | AP3: 0.035714021 | AQ3: ='FCE calculation'!F7 -> 3.4717225 | AR3: =(AF3+AG3+AH3)/AQ3 -> 4.5749701 | AS3: =(AF3)/AQ3 -> 3.8946521 | AT3: =AR3-AS3 -> 0.68031798 | AU3: =AT3/AR3 -> 0.14870436 | AW3: =AJ3/AV3 -> #DIV/0! | AY3: =AI3/AX3 -> #DIV/0!
B4: 2021-22 | C4: Waimakariri, Selwyn, Hurunui & Ashburton | D4: Owner operator | E4: 27 | F4: 6120.4637 | G4: -9.8029851 | H4: 6110.6607 | I4: 0.070153415 | J4: 0.88313888 | K4: -0.020670993 | L4: 0.064528388 | M4: 0.96833826 | N4: 0.486424 | O4: 0.1084172 | P4: 0.081526066 | Q4: 0.13042717 | R4: 0.80679443 | S4: 1.7751327 | T4: 1389.0948 | U4: -30.300791 | V4: 96.093729 | W4: 1515.4893 | X4: 810.53203 | Y4: 193.20674 | Z4: 108.80596 | AA4: 170.7737 | AB4: 1283.3184 | AC4: 2798.8077 | AD4: 14.293977 | AE4: 0.20434689 | AF4: 14.089631 | AG4: 2.084738 | AH4: 0.10986739 | AI4: 2.2592502 | AJ4: 2.7468115 | AK4: 21.290298 | AL4: 615.90358 | AM4: 0.47562689 | AN4: 0.10728758 | AO4: 0.16522746 | AP4: 0.20558033 | AQ4: ='FCE calculation'!F8 -> 3.4857068 | AR4: =(AF4+AG4+AH4)/AQ4 -> 4.671717 | AS4: =(AF4)/AQ4 -> 4.0421158 | AT4: =AR4-AS4 -> 0.62960126 | AU4: =AT4/AR4 -> 0.13476871 | AW4: =AJ4/AV4 -> #DIV/0! | AY4: =AI4/AX4 -> #DIV/0!
B5: 2020-21 | C5: Waimakariri, Selwyn, Hurunui & Ashburton | D5: Owner operator | E5: 31 | F5: 4546.1295 | G5: 2.887176 | H5: 4549.0167 | I5: 0.054794446 | J5: 0.84703957 | K5: -0.0024249939 | L5: 0.044225074 | M5: 0.89368964 | N5: 0.45701688 | O5: 0.062412744 | P5: 0.028334431 | Q5: 0.13411229 | R5: 0.68187635 | S5: 1.575566 | T5: 1451.0782 | U5: -3.102827 | V5: 77.39552 | W5: 1531.5765 | X5: 778.40944 | Y5: 111.40083 | Z5: 46.255365 | AA5: 208.71321 | AB5: 1144.7789 | AC5: 2676.3554 | AD5: 15.485006 | AE5: 0.16912637 | AF5: 15.31588 | AG5: 2.2514815 | AH5: 0.062441492 | AI5: 2.5213038 | AJ5: 2.2998752 | AK5: 22.450982 | AL5: 631.99432 | AM5: 0.51240264 | AN5: 0.067669606 | AO5: 0.11307336 | AP5: 0.10909791 | AQ5: ='FCE calculation'!F9 -> 3.4827511 | AR5: =(AF5+AG5+AH5)/AQ5 -> 5.0620334 | AS5: =(AF5)/AQ5 -> 4.3976383 | AT5: =AR5-AS5 -> 0.66439514 | AU5: =AT5/AR5 -> 0.13125064 | AW5: =AJ5/AV5 -> #DIV/0! | AY5: =AI5/AX5 -> #DIV/0!
B6: 2019-20 | C6: Waimakariri, Selwyn, Hurunui & Ashburton | D6: Owner operator | E6: 27 | F6: 4348.408 | G6: 12.74283 | H6: 4361.1509 | I6: 0.056024026 | J6: 0.80470969 | K6: -0.022457561 | L6: 0.037439972 | M6: 0.86460723 | N6: 0.45927194 | O6: 0.12079907 | P6: 0.022711776 | Q6: 0.10855914 | R6: 0.71134192 | S6: 1.5759491 | T6: 1363.6837 | U6: -33.946254 | V6: 60.960668 | W6: 1458.5906 | X6: 768.17815 | Y6: 188.91982 | Z6: 38.593629 | AA6: 168.66836 | AB6: 1164.36 | AC6: 2622.9506 | AD6: 15.246579 | AE6: 0.13386388 | AF6: 15.112715 | AG6: 2.1884885 | AH6: 0.098379998 | AI6: 2.4998679 | AJ6: 1.9567312 | AK6: 21.856182 | AL6: 631.63308 | AM6: 0.54520472 | AN6: 0.048168608 | AO6: 0.10480439 | AP6: 0.074615216 | AQ6: ='FCE calculation'!F10 -> 3.4783549 | AR6: =(AF6+AG6+AH6)/AQ6 -> 5.002245 | AS6: =(AF6)/AQ6 -> 4.3447881 | AT6: =AR6-AS6 -> 0.65745694 | AU6: =AT6/AR6 -> 0.13143237 | AW6: =AJ6/AV6 -> #DIV/0! | AY6: =AI6/AX6 -> #DIV/0!
F7: =AVERAGE(F3:F6) -> 4772.8345 | AF7: =AVERAGE(AF3:AF6) -> 14.509844 | AG7: =AVERAGE(AG3:AG6) -> 2.1765042 | AH7: =AVERAGE(AH3:AH6) -> 0.11281388 | AI7: =AVERAGE(AI3:AI6) -> 2.3738965 | AJ7: =AVERAGE(AJ3:AJ6) -> 2.3991499 | AK7: =AVERAGE(AK3:AK6) -> 21.572209 | AM7: =AVERAGE(AM3:AM6) -> 0.50508116 | AQ7: =AVERAGE(AQ3:AQ6) -> 3.4796338 | AR7: =AVERAGE(AR3:AR6) -> 4.8277414 | AS7: =AVERAGE(AS3:AS6) -> 4.1697986 | AT7: =AVERAGE(AT3:AT6) -> 0.65794283 | AU7: =AVERAGE(AU3:AU6) -> 0.13653902 | AV7: =AVERAGE(AV3:AV6) -> #DIV/0! | AW7: =AVERAGE(AW3:AW6) -> #DIV/0! | AX7: =AVERAGE(AX3:AX6) -> #DIV/0! | AY7: =AVERAGE(AY3:AY6) -> #DIV/0!
AF8: =AF7*120% -> 17.411813 | AG8: =AG7*110% -> 2.3941546 | AH8: =AVERAGE(AH4:AH7) -> 0.09587569 | AI8: =AVERAGE(AI4:AI7) -> 2.4135796 | AJ8: =AVERAGE(AJ4:AJ7) -> 2.3506419 | AK8: =AVERAGE(AK4:AK7) -> 21.792418 | AR8: =AR7*120% -> 5.7932897 | AS8: =AS7*120% -> 5.0037583 | AT8: =AT7*110% -> 0.72373711 | AW8: =AW7*120% -> #DIV/0! | AY8: =AY7*120% -> #DIV/0!

Sheet Milk production
B2: Reference = DairyNZ production statistics - LIC Herd testing data
B3: Average litres of milk per day
B4: Region | C4: Season | D4: June | E4: July | F4: August | G4: September | H4: October | I4: November | J4: December | K4: January | L4: February | M4: March | N4: April | O4: May
D5: 30 | E5: 31 | F5: 31 | G5: 30 | H5: 31 | I5: 30 | J5: 31 | K5: 31 | L5: 28 | M5: 31 | N5: 30 | O5: 31
B6: North Canterbury | C6: ='FCE calculation'!C7 -> 2022-23 | D6: 18.7 | E6: 18 | F6: 21.04 | G6: 24.44 | H6: 24.53 | I6: 23.91 | J6: 21.71 | K6: 19.78 | L6: 18.44 | M6: 16.02 | N6: 14.14 | O6: 13.54 | P6: =AVERAGE(D6:O6) -> 19.520833
B7: North Canterbury | C7: ='FCE calculation'!C8 -> 2021-22 | D7: 19.03 | E7: 20.95 | F7: 20.75 | G7: 24.83 | H7: 25.57 | I7: 23.36 | J7: 21.3 | K7: 20.02 | L7: 18.07 | M7: 16.01 | N7: 14.4 | O7: 13.22 | P7: =AVERAGE(D7:O7) -> 19.7925
B8: North Canterbury | C8: ='FCE calculation'!C9 -> 2020-21 | D8: 19.6 | E8: 20.59 | F8: 22.89 | G8: 25.65 | H8: 26.67 | I8: 24.25 | J8: 23.21 | K8: 21.08 | L8: 19.69 | M8: 16.62 | N8: 14.85 | O8: 13.72 | P8: =AVERAGE(D8:O8) -> 20.735
B9: North Canterbury | C9: ='FCE calculation'!C10 -> 2019-20 | D9: 19.93 | E9: 20.91 | F9: 21.8 | G9: 25.93 | H9: 26.08 | I9: 24.26 | J9: 23.12 | K9: 21.41 | L9: 19.03 | M9: 16.26 | N9: 14.59 | O9: 14.2 | P9: =AVERAGE(D9:O9) -> 20.626667
B10: Average | D10: =AVERAGE(D6:D9) -> 19.315 | E10: =AVERAGE(E6:E9) -> 20.1125 | F10: =AVERAGE(F6:F9) -> 21.62 | G10: =AVERAGE(G6:G9) -> 25.2125 | H10: =AVERAGE(H6:H9) -> 25.7125 | I10: =AVERAGE(I6:I9) -> 23.945 | J10: =AVERAGE(J6:J9) -> 22.335 | K10: =AVERAGE(K6:K9) -> 20.5725 | ... O10: =AVERAGE(O6:O9) -> 13.67 | P10: =AVERAGE(D10:O10) -> 20.16875
B12: Average kg milkfat per cow per day | P12: Average
B13: =B6 -> North Canterbury | C13: =C6 -> 2022-23 | D13: 0.9 | E13: 0.92 | F13: 0.97 | G13: 1.1 | H13: 1.11 | I13: 1.08 | J13: 1.02 | K13: 0.96 | L13: 0.93 | M13: 0.87 | N13: 0.81 | O13: 0.76 | P13: =AVERAGE(D13:O13) -> 0.9525
B14: =B7 -> North Canterbury | C14: =C7 -> 2021-22 | D14: 0.98 | E14: 0.98 | F14: 0.96 | G14: 1.11 | H14: 1.15 | I14: 1.07 | J14: 1.01 | K14: 0.96 | L14: 0.92 | M14: 0.85 | N14: 0.81 | O14: 0.75 | P14: =AVERAGE(D14:O14) -> 0.9625
B15: =B8 -> North Canterbury | C15: =C8 -> 2020-21 | D15: 0.99 | E15: 0.99 | F15: 1.02 | G15: 1.14 | H15: 1.19 | I15: 1.09 | J15: 1.05 | K15: 1 | L15: 0.97 | M15: 0.88 | N15: 0.83 | O15: 0.81 | P15: =AVERAGE(D15:O15) -> 0.99666667
B16: =B9 -> North Canterbury | C16: =C9 -> 2019-20 | D16: 0.95 | E16: 0.97 | F16: 0.97 | G16: 1.15 | H16: 1.17 | I16: 1.09 | J16: 1.06 | K16: 1.01 | L16: 0.94 | M16: 0.86 | N16: 0.82 | O16: 0.81 | P16: =AVERAGE(D16:O16) -> 0.98333333
B17: =B10 -> Average | D17: =AVERAGE(D13:D16) -> 0.955 | E17: =AVERAGE(E13:E16) -> 0.965 | F17: =AVERAGE(F13:F16) -> 0.98 | G17: =AVERAGE(G13:G16) -> 1.125 | H17: =AVERAGE(H13:H16) -> 1.155 | I17: =AVERAGE(I13:I16) -> 1.0825 | J17: =AVERAGE(J13:J16) -> 1.035 | K17: =AVERAGE(K13:K16) -> 0.9825 | ... O17: =AVERAGE(O13:O16) -> 0.7825 | P17: =AVERAGE(D17:O17) -> 0.97375
B19: =B13 -> North Canterbury | C19: =C13 -> 2022-23 | D19: =D13/D6 -> 0.048128342 | E19: =E13/E6 -> 0.051111111 | F19: =F13/F6 -> 0.046102662 | G19: =G13/G6 -> 0.045008183 | H19: =H13/H6 -> 0.045250713 | I19: =I13/I6 -> 0.045169385 | J19: =J13/J6 -> 0.046982957 | K19: =K13/K6 -> 0.048533873 | ... O19: =O13/O6 -> 0.056129985 | P19: =AVERAGE(D19:O19) -> 0.049536872
B20: =B14 -> North Canterbury | C20: =C14 -> 2021-22 | D20: =D14/D7 -> 0.051497635 | E20: =E14/E7 -> 0.046778043 | F20: =F14/F7 -> 0.04626506 | G20: =G14/G7 -> 0.044703987 | H20: =H14/H7 -> 0.04497458 | I20: =I14/I7 -> 0.045804795 | J20: =J14/J7 -> 0.04741784 | K20: =K14/K7 -> 0.047952048 | ... O20: =O14/O7 -> 0.056732224 | P20: =AVERAGE(D20:O20) -> 0.049365095
B21: =B15 -> North Canterbury | C21: =C15 -> 2020-21 | D21: =D15/D8 -> 0.050510204 | E21: =E15/E8 -> 0.048081593 | F21: =F15/F8 -> 0.044560944 | G21: =G15/G8 -> 0.044444444 | H21: =H15/H8 -> 0.044619423 | I21: =I15/I8 -> 0.044948454 | J21: =J15/J8 -> 0.045239121 | K21: =K15/K8 -> 0.04743833 | ... O21: =O15/O8 -> 0.059037901 | P21: =AVERAGE(D21:O21) -> 0.048915376
B22: =B16 -> North Canterbury | C22: =C16 -> 2019-20 | D22: =D16/D9 -> 0.047666834 | E22: =E16/E9 -> 0.046389287 | F22: =F16/F9 -> 0.044495413 | G22: =G16/G9 -> 0.044350174 | H22: =H16/H9 -> 0.044861963 | I22: =I16/I9 -> 0.044929926 | J22: =J16/J9 -> 0.045847751 | K22: =K16/K9 -> 0.047174218 | ... O22: =O16/O9 -> 0.057042254 | P22: =AVERAGE(D22:O22) -> 0.048437243
B24: Average kg protein per cow per day | P24: Average
B25: =B13 -> North Canterbury | C25: =C13 -> 2022-23 | D25: 0.72 | E25: 0.7 | F25: 0.78 | G25: 0.92 | H25: 0.94 | I25: 0.91 | J25: 0.84 | K25: 0.79 | L25: 0.75 | M25: 0.7 | N25: 0.65 | O25: 0.62 | P25: =AVERAGE(D25:O25) -> 0.77666667
B26: =B14 -> North Canterbury | C26: =C14 -> 2021-22 | D26: 0.78 | E26: 0.8 | F26: 0.78 | G26: 0.93 | H26: 0.97 | I26: 0.89 | J26: 0.83 | K26: 0.8 | L26: 0.74 | M26: 0.69 | N26: 0.66 | O26: 0.62 | P26: =AVERAGE(D26:O26) -> 0.79083333
B27: =B15 -> North Canterbury | C27: =C15 -> 2020-21 | D27: 0.78 | E27: 0.79 | F27: 0.84 | G27: 0.98 | H27: 1.01 | I27: 0.92 | J27: 0.9 | K27: 0.83 | L27: 0.8 | M27: 0.72 | N27: 0.68 | O27: 0.65 | P27: =AVERAGE(D27:O27) -> 0.825
B28: =B16 -> North Canterbury | C28: =C16 -> 2019-20 | D28: 0.78 | E28: 0.8 | F28: 0.81 | G28: 0.99 | H28: 1 | I28: 0.92 | J28: 0.89 | K28: 0.85 | L28: 0.76 | M28: 0.71 | N28: 0.68 | O28: 0.67 | P28: =AVERAGE(D28:O28) -> 0.82166667
B29: =B17 -> Average | D29: =AVERAGE(D25:D28) -> 0.765 | E29: =AVERAGE(E25:E28) -> 0.7725 | F29: =AVERAGE(F25:F28) -> 0.8025 | G29: =AVERAGE(G25:G28) -> 0.955 | H29: =AVERAGE(H25:H28) -> 0.98 | I29: =AVERAGE(I25:I28) -> 0.91 | J29: =AVERAGE(J25:J28) -> 0.865 | K29: =AVERAGE(K25:K28) -> 0.8175 | ... O29: =AVERAGE(O25:O28) -> 0.64 | P29: =AVERAGE(D29:O29) -> 0.80354167
B31: =B25 -> North Canterbury | C31: =C25 -> 2022-23 | D31: =D25/D6 -> 0.038502674 | E31: =E25/E6 -> 0.038888889 | F31: =F25/F6 -> 0.037072243 | G31: =G25/G6 -> 0.037643208 | H31: =H25/H6 -> 0.038320424 | I31: =I25/I6 -> 0.038059389 | J31: =J25/J6 -> 0.038691847 | K31: =K25/K6 -> 0.039939333 | ... O31: =O25/O6 -> 0.045790251 | P31: =AVERAGE(D31:O31) -> 0.040270414
B32: =B26 -> North Canterbury | C32: =C26 -> 2021-22 | D32: =D26/D7 -> 0.040987914 | E32: =E26/E7 -> 0.038186158 | F32: =F26/F7 -> 0.037590361 | G32: =G26/G7 -> 0.037454692 | H32: =H26/H7 -> 0.03793508 | I32: =I26/I7 -> 0.038099315 | J32: =J26/J7 -> 0.038967136 | K32: =K26/K7 -> 0.03996004 | ... O32: =O26/O7 -> 0.046898638 | P32: =AVERAGE(D32:O32) -> 0.040496882
B33: =B27 -> North Canterbury | C33: =C27 -> 2020-21 | D33: =D27/D8 -> 0.039795918 | E33: =E27/E8 -> 0.03836814 | F33: =F27/F8 -> 0.036697248 | G33: =G27/G8 -> 0.038206628 | H33: =H27/H8 -> 0.037870266 | I33: =I27/I8 -> 0.037938144 | J33: =J27/J8 -> 0.038776389 | K33: =K27/K8 -> 0.039373814 | ... O33: =O27/O8 -> 0.047376093 | P33: =AVERAGE(D33:O33) -> 0.040345412
B34: =B28 -> North Canterbury | C34: =C28 -> 2019-20 | D34: =D28/D9 -> 0.039136979 | E34: =E28/E9 -> 0.038259206 | F34: =F28/F9 -> 0.037155963 | G34: =G28/G9 -> 0.038179715 | H34: =H28/H9 -> 0.038343558 | I34: =I28/I9 -> 0.037922506 | J34: =J28/J9 -> 0.03849481 | K34: =K28/K9 -> 0.039701074 | ... O34: =O28/O9 -> 0.047183099 | P34: =AVERAGE(D34:O34) -> 0.040382213
B36: Average kg MS per day
B37: =B6 -> North Canterbury | C37: =C6 -> 2022-23 | D37: =(D6*1.03)*(D19+D31) -> 1.6686 | E37: =(E6*1.03)*(E19+E31) -> 1.6686 | F37: =(F6*1.03)*(F19+F31) -> 1.8025 | G37: =(G6*1.03)*(G19+G31) -> 2.0806 | H37: =(H6*1.03)*(H19+H31) -> 2.1115 | I37: =(I6*1.03)*(I19+I31) -> 2.0497 | J37: =(J6*1.03)*(J19+J31) -> 1.9158 | K37: =(K6*1.03)*(K19+K31) -> 1.8025 | ... O37: =(O6*1.03)*(O19+O31) -> 1.4214 | P37: =AVERAGE(D37:O37) -> 1.7810417
B38: =B7 -> North Canterbury | C38: =C7 -> 2021-22 | D38: =(D7*1.03)*(D20+D32) -> 1.8128 | E38: =(E7*1.03)*(E20+E32) -> 1.8334 | F38: =(F7*1.03)*(F20+F32) -> 1.7922 | G38: =(G7*1.03)*(G20+G32) -> 2.1012 | H38: =(H7*1.03)*(H20+H32) -> 2.1836 | I38: =(I7*1.03)*(I20+I32) -> 2.0188 | J38: =(J7*1.03)*(J20+J32) -> 1.8952 | K38: =(K7*1.03)*(K20+K32) -> 1.8128 | ... O38: =(O7*1.03)*(O20+O32) -> 1.4111 | P38: =AVERAGE(D38:O38) -> 1.8059333
B39: =B8 -> North Canterbury | C39: =C8 -> 2020-21 | D39: =(D8*1.03)*(D21+D33) -> 1.8231 | E39: =(E8*1.03)*(E21+E33) -> 1.8334 | F39: =(F8*1.03)*(F21+F33) -> 1.9158 | G39: =(G8*1.03)*(G21+G33) -> 2.1836 | H39: =(H8*1.03)*(H21+H33) -> 2.266 | I39: =(I8*1.03)*(I21+I33) -> 2.0703 | J39: =(J8*1.03)*(J21+J33) -> 2.0085 | K39: =(K8*1.03)*(K21+K33) -> 1.8849 | ... O39: =(O8*1.03)*(O21+O33) -> 1.5038 | P39: =AVERAGE(D39:O39) -> 1.8763167
B40: =B9 -> North Canterbury | C40: =C9 -> 2019-20 | D40: =(D9*1.03)*(D22+D34) -> 1.7819 | E40: =(E9*1.03)*(E22+E34) -> 1.8231 | F40: =(F9*1.03)*(F22+F34) -> 1.8334 | G40: =(G9*1.03)*(G22+G34) -> 2.2042 | H40: =(H9*1.03)*(H22+H34) -> 2.2351 | I40: =(I9*1.03)*(I22+I34) -> 2.0703 | J40: =(J9*1.03)*(J22+J34) -> 2.0085 | K40: =(K9*1.03)*(K22+K34) -> 1.9158 | ... O40: =(O9*1.03)*(O22+O34) -> 1.5244 | P40: =AVERAGE(D40:O40) -> 1.85915
B41: =B10 -> Average | D41: =AVERAGE(D37:D40) -> 1.7716 | E41: =AVERAGE(E37:E40) -> 1.789625 | F41: =AVERAGE(F37:F40) -> 1.835975 | G41: =AVERAGE(G37:G40) -> 2.1424 | H41: =AVERAGE(H37:H40) -> 2.19905 | I41: =AVERAGE(I37:I40) -> 2.052275 | J41: =AVERAGE(J37:J40) -> 1.957 | K41: =AVERAGE(K37:K40) -> 1.854 | ... O41: =AVERAGE(O37:O40) -> 1.465175 | P41: =AVERAGE(D41:O41) -> 1.8306104
B43: Average kg MS per month
B44: =B37 -> North Canterbury | C44: =C37 -> 2022-23 | D44: =D37*D$5 -> 50.058 | E44: =E37*E$5 -> 51.7266 | F44: =F37*F$5 -> 55.8775 | G44: =G37*G$5 -> 62.418 | H44: =H37*H$5 -> 65.4565 | I44: =I37*I$5 -> 61.491 | J44: =J37*J$5 -> 59.3898 | K44: =K37*K$5 -> 55.8775 | ... O44: =O37*O$5 -> 44.0634 | P44: =AVERAGE(D44:O44) -> 54.171133
B45: =B38 -> North Canterbury | C45: =C38 -> 2021-22 | D45: =D38*D$5 -> 54.384 | E45: =E38*E$5 -> 56.8354 | F45: =F38*F$5 -> 55.5582 | G45: =G38*G$5 -> 63.036 | H45: =H38*H$5 -> 67.6916 | I45: =I38*I$5 -> 60.564 | J45: =J38*J$5 -> 58.7512 | K45: =K38*K$5 -> 56.1968 | ... O45: =O38*O$5 -> 43.7441 | P45: =AVERAGE(D45:O45) -> 54.935908
B46: =B39 -> North Canterbury | C46: =C39 -> 2020-21 | D46: =D39*D$5 -> 54.693 | E46: =E39*E$5 -> 56.8354 | F46: =F39*F$5 -> 59.3898 | G46: =G39*G$5 -> 65.508 | H46: =H39*H$5 -> 70.246 | I46: =I39*I$5 -> 62.109 | J46: =J39*J$5 -> 62.2635 | K46: =K39*K$5 -> 58.4319 | ... O46: =O39*O$5 -> 46.6178 | P46: =AVERAGE(D46:O46) -> 57.074017
B47: =B40 -> North Canterbury | C47: =C40 -> 2019-20 | D47: =D40*D$5 -> 53.457 | E47: =E40*E$5 -> 56.5161 | F47: =F40*F$5 -> 56.8354 | G47: =G40*G$5 -> 66.126 | H47: =H40*H$5 -> 69.2881 | I47: =I40*I$5 -> 62.109 | J47: =J40*J$5 -> 62.2635 | K47: =K40*K$5 -> 59.3898 | ... O47: =O40*O$5 -> 47.2564 | P47: =AVERAGE(D47:O47) -> 56.56245
...

Sheet Herd Distribution
B2: Ref DairyNZ production statistics North Canterbury
B3: Average herd size
B4: ='Milk production'!B6 -> North Canterbury | C4: ='Milk production'!C6 -> 2022-23 | D4: 792
B5: ='Milk production'!B7 -> North Canterbury | C5: ='Milk production'!C7 -> 2021-22 | D5: 820
B6: ='Milk production'!B8 -> North Canterbury | C6: ='Milk production'!C8 -> 2020-21 | D6: 818
B7: ='Milk production'!B9 -> North Canterbury | C7: ='Milk production'!C9 -> 2019-20 | D7: 815
B8: Average herd size | D8: =AVERAGE(D4:D7) -> 811.25
B10: Ref Primary Insight client Overseer data North Canterbury
B11: Average herd distribution (Dairy Farm 1) | D11: ='Milk production'!D4 -> June | E11: ='Milk production'!E4 -> July | F11: ='Milk production'!F4 -> August | G11: ='Milk production'!G4 -> September | H11: ='Milk production'!H4 -> October | I11: ='Milk production'!I4 -> November | J11: ='Milk production'!J4 -> December | K11: ='Milk production'!K4 -> January | ... O11: ='Milk production'!O4 -> May
B12: =B4 -> North Canterbury | C12: =C4 -> 2022-23 | D12: 6 | E12: 302 | F12: 907 | G12: 904 | H12: 891 | I12: 890 | J12: 882 | K12: 880 | L12: 864 | M12: 759 | N12: 741 | O12: 6
B13: =B5 -> North Canterbury | C13: =C5 -> 2021-22 | D13: 12 | E13: 308 | F13: 915 | G13: 914 | H13: 910 | I13: 911 | J13: 884 | K13: 879 | L13: 877 | M13: 842 | N13: 791 | O13: 228
B14: =B6 -> North Canterbury | C14: =C6 -> 2020-21 | D14: 0 | E14: 299 | F14: 899 | G14: 881 | H14: 878 | I14: 854 | J14: 853 | K14: 852 | L14: 849 | M14: 805 | N14: 757 | O14: 707
B15: =B7 -> North Canterbury | C15: =C7 -> 2019-20 | D15: 0 | E15: 285 | F15: 856 | G15: 856 | H15: 853 | I15: 842 | J15: 839 | K15: 839 | L15: 837 | M15: 800 | N15: 766 | O15: 648
B16: Average distribution | C16: % | D16: =AVERAGE(D12:D15)/AVERAGE($F$12:$F$15) -> 0.0050321498 | E16: =AVERAGE(E12:E15)/AVERAGE($F$12:$F$15) -> 0.33379927 | F16: =AVERAGE(F12:F15)/AVERAGE($F$12:$F$15) -> 1 | G16: =AVERAGE(G12:G15)/AVERAGE($F$12:$F$15) -> 0.99384959 | H16: =AVERAGE(H12:H15)/AVERAGE($F$12:$F$15) -> 0.98741963 | I16: =AVERAGE(I12:I15)/AVERAGE($F$12:$F$15) -> 0.97763489 | J16: =AVERAGE(J12:J15)/AVERAGE($F$12:$F$15) -> 0.9667319 | K16: =AVERAGE(K12:K15)/AVERAGE($F$12:$F$15) -> 0.96449539 | ... O16: =AVERAGE(O12:O15)/AVERAGE($F$12:$F$15) -> 0.44422701
B18: Average herd distribution (Dairy Farm 2)
B19: =B12 -> North Canterbury | C19: =C12 -> 2022-23 | D19: 0 | E19: 222 | F19: 406 | G19: 394 | H19: 393 | I19: 392 | J19: 391 | K19: 391 | L19: 375 | M19: 370 | N19: 330 | O19: 0
B20: =B13 -> North Canterbury | C20: =C13 -> 2021-22 | D20: 5 | E20: 269 | F20: 408 | G20: 400 | H20: 394 | I20: 390 | J20: 390 | K20: 390 | L20: 385 | M20: 371 | N20: 370 | O20: 5
B21: =B14 -> North Canterbury | C21: =C14 -> 2020-21 | D21: 0 | E21: 246 | F21: 422 | G21: 411 | H21: 405 | I21: 401 | J21: 399 | K21: 398 | L21: 385 | M21: 381 | N21: 381 | O21: 0
B22: =B15 -> North Canterbury | C22: =C15 -> 2019-20 | D22: 0 | E22: 200 | F22: 315 | G22: 415 | H22: 415 | I22: 415 | J22: 415 | K22: 415 | L22: 415 | M22: 370 | N22: 390 | O22: 0
B23: =B16 -> Average distribution | C23: =C16 -> % | D23: =AVERAGE(D19:D22)/AVERAGE($F$19:$F$21,$G$22) -> 0.0030284676 | E23: =AVERAGE(E19:E22)/AVERAGE($F$19:$F$21,$G$22) -> 0.56753483 | F23: =AVERAGE(F19:F22)/AVERAGE($F$19:$F$21,$G$22) -> 0.93943065 | G23: =AVERAGE(G19:G22)/AVERAGE($F$19:$F$21,$G$22) -> 0.9812235 | H23: =AVERAGE(H19:H22)/AVERAGE($F$19:$F$21,$G$22) -> 0.97334949 | I23: =AVERAGE(I19:I22)/AVERAGE($F$19:$F$21,$G$22) -> 0.96789824 | J23: =AVERAGE(J19:J22)/AVERAGE($F$19:$F$21,$G$22) -> 0.96608116 | K23: =AVERAGE(K19:K22)/AVERAGE($F$19:$F$21,$G$22) -> 0.96547547 | ... O23: =AVERAGE(O19:O22)/AVERAGE($F$19:$F$21,$G$22) -> 0.0030284676
B25: Average herd distribution (Dairy Farm 3)
B26: =B19 -> North Canterbury | C26: =C19 -> 2022-23 | D26: 0 | E26: 314 | F26: 943 | G26: 937 | H26: 922 | I26: 920 | J26: 912 | K26: 912 | L26: 880 | M26: 774 | N26: 772 | O26: 0
B27: =B20 -> North Canterbury | C27: =C20 -> 2021-22 | D27: 16 | E27: 402 | F27: 1206 | G27: 1239 | H27: 1230 | I27: 1127 | J27: 976 | K27: 915 | L27: 913 | M27: 874 | N27: 798 | O27: 503
B28: =B21 -> North Canterbury | C28: =C21 -> 2020-21 | D28: 0 | E28: 318 | F28: 955 | G28: 937 | H28: 932 | I28: 907 | J28: 906 | K28: 905 | L28: 896 | M28: 849 | N28: 727 | O28: 727
B29: =B22 -> North Canterbury | C29: =C22 -> 2019-20 | D29: 0 | E29: 922 | F29: 922 | G29: 912 | H29: 892 | I29: 888 | J29: 888 | K29: 888 | L29: 886 | M29: 1077 | N29: 874 | O29: 812
B30: Average distribution | C30: % | D30: =AVERAGE(D26:D29)/AVERAGE($F$26:$F$29) -> 0.0039741679 | E30: =AVERAGE(E26:E29)/AVERAGE($F$26:$F$29) -> 0.48584203 | F30: =AVERAGE(F26:F29)/AVERAGE($F$26:$F$29) -> 1 | G30: =AVERAGE(G26:G29)/AVERAGE($F$26:$F$29) -> 0.99975161 | H30: =AVERAGE(H26:H29)/AVERAGE($F$26:$F$29) -> 0.98758073 | I30: =AVERAGE(I26:I29)/AVERAGE($F$26:$F$29) -> 0.95429707 | J30: =AVERAGE(J26:J29)/AVERAGE($F$26:$F$29) -> 0.91455539 | K30: =AVERAGE(K26:K29)/AVERAGE($F$26:$F$29) -> 0.89915549 | ... O30: =AVERAGE(O26:O29)/AVERAGE($F$26:$F$29) -> 0.50720318
B32: Average herd distribution (Dairy Farm 4)
B33: =B26 -> North Canterbury | C33: =C26 -> 2022-23 | D33: 20 | E33: 343 | F33: 1031 | G33: 1027 | H33: 1023 | I33: 1022 | J33: 1003 | K33: 1003 | L33: 1002 | M33: 896 | N33: 843 | O33: 20
B34: =B27 -> North Canterbury | C34: =C27 -> 2021-22 | D34: 21 | E34: 349 | F34: 1048 | G34: 1046 | H34: 1032 | I34: 1032 | J34: 1027 | K34: 1002 | L34: 1000 | M34: 970 | N34: 882 | O34: 548
B35: =B28 -> North Canterbury | C35: =C28 -> 2020-21 | D35: 0 | E35: 347 | F35: 1041 | G35: 1032 | H35: 1019 | I35: 1005 | J35: 1001 | K35: 1001 | L35: 993 | M35: 992 | N35: 857 | O35: 803
B36: =B29 -> North Canterbury | C36: =C29 -> 2019-20 | D36: 0 | E36: 308 | F36: 925 | G36: 925 | H36: 922 | I36: 917 | J36: 898 | K36: 897 | L36: 901 | M36: 878 | N36: 883 | O36: 1014
B37: =B30 -> Average distribution | C37: =C30 -> % | D37: =AVERAGE(D33:D36)/AVERAGE($F$33:$F$36) -> 0.01013597 | E37: =AVERAGE(E33:E36)/AVERAGE($F$33:$F$36) -> 0.33300371 | F37: =AVERAGE(F33:F36)/AVERAGE($F$33:$F$36) -> 1 | G37: =AVERAGE(G33:G36)/AVERAGE($F$33:$F$36) -> 0.99629172 | H37: =AVERAGE(H33:H36)/AVERAGE($F$33:$F$36) -> 0.98788628 | I37: =AVERAGE(I33:I36)/AVERAGE($F$33:$F$36) -> 0.9829419 | J37: =AVERAGE(J33:J36)/AVERAGE($F$33:$F$36) -> 0.97132262 | K37: =AVERAGE(K33:K36)/AVERAGE($F$33:$F$36) -> 0.96489493 | ... O37: =AVERAGE(O33:O36)/AVERAGE($F$33:$F$36) -> 0.58961681
B39: Average herd distribution (Dairy Farm 5)
B40: =B19 -> North Canterbury | C40: =C19 -> 2022-23 | D40: 0 | E40: 485 | F40: 752 | G40: 750 | H40: 750 | I40: 750 | J40: 750 | K40: 750 | L40: 715 | M40: 715 | N40: 675 | O40: 0
B41: =B20 -> North Canterbury | C41: =C20 -> 2021-22 | D41: 0 | E41: 465 | F41: 734 | G41: 732 | H41: 731 | I41: 731 | J41: 731 | K41: 731 | L41: 696 | M41: 696 | N41: 656 | O41: 0
B42: =B23 -> Average distribution | C42: =C23 -> % | D42: =AVERAGE(D40:D41)/AVERAGE($F$40:$F$41) -> 0 | E42: =AVERAGE(E40:E41)/AVERAGE($F$40:$F$41) -> 0.63930013 | F42: =AVERAGE(F40:F41)/AVERAGE($F$40:$F$41) -> 1 | G42: =AVERAGE(G40:G41)/AVERAGE($F$40:$F$41) -> 0.99730821 | H42: =AVERAGE(H40:H41)/AVERAGE($F$40:$F$41) -> 0.99663526 | I42: =AVERAGE(I40:I41)/AVERAGE($F$40:$F$41) -> 0.99663526 | J42: =AVERAGE(J40:J41)/AVERAGE($F$40:$F$41) -> 0.99663526 | K42: =AVERAGE(K40:K41)/AVERAGE($F$40:$F$41) -> 0.99663526 | ... O42: =AVERAGE(O40:O41)/AVERAGE($F$40:$F$41) -> 0
B44: Average herd distribution (Dairy Farm 6)
B45: =B40 -> North Canterbury | C45: =C40 -> 2022-23 | D45: 0 | E45: 120 | F45: 720 | G45: 720 | H45: 720 | I45: 720 | J45: 720 | K45: 670 | L45: 645 | M45: 615 | N45: 525 | O45: 0
B46: =B42 -> Average distribution | C46: =C42 -> % | D46: =D45/$F$45 -> 0 | E46: =E45/$F$45 -> 0.16666667 | F46: =F45/$F$45 -> 1 | G46: =G45/$F$45 -> 1 | H46: =H45/$F$45 -> 1 | I46: =I45/$F$45 -> 1 | J46: =J45/$F$45 -> 1 | K46: =K45/$F$45 -> 0.93055556 | ... O46: =O45/$F$45 -> 0
B48: Average herd distribution (Dairy Farm 7)
...

Sheet Payout
C2: Fonterra | D2: Synlait | E2: Open Country | F2: Westland | H2: Average
B3: 2023-24 | C3: 8.2 | D3: 7.25 | E3: 8.3 | F3: 7.9 | H3: =AVERAGE(C3:F3) -> 7.9125 | J3: Estimated
B4: 2022-23 | C4: 8.72 | D4: 8.2 | E4: 8.33 | F4: 8.32 | H4: =AVERAGE(C4:F4) -> 8.3925
B5: 2021-22 | C5: 9.5 | D5: 9.3 | E5: 9.45 | F5: 9.4 | H5: =AVERAGE(C5:F5) -> 9.4125
B6: 2020-21 | C6: 7.74 | D6: 7.55 | E6: 7.61 | F6: 7.5 | H6: =AVERAGE(C6:F6) -> 7.6
B7: 2019-20 | C7: 7.19 | D7: 7.3 | E7: 7.27 | F7: 6.75 | H7: =AVERAGE(C7:F7) -> 7.1275
B9: Average | C9: =AVERAGE(C3:C7) -> 8.27 | D9: =AVERAGE(D3:D7) -> 7.92 | E9: =AVERAGE(E3:E7) -> 8.192 | F9: =AVERAGE(F3:F7) -> 7.974 | H9: =AVERAGE(C9:F9) -> 8.089

Sheet Feed costs
C2: Per bale | D2: Cost per t DM
B3: Baleage purchase | C3: 130 | D3: =((1000/$C$17)*(C3)) -> 371.42857 | E3: Trademe + Feedfinder + Local Contractors
B5: Transport | C5: 12 | D5: =(1000/$C$17)*(C5) -> 34.285714 | E5: Cartage companies - 50 bale truck and trailer within 50km radius
B7: Baleage making (mow, rake, bale, wrap + stack) | C7: 56 | D7: =((1000/$C$17)*(C7)) -> 160 | E7: Lincoln Financial Manual + Local Contractors
B9: Feeding out (time + cost) | C9: =C19/C18 -> 37.5 | D9: =((1000/$C$17)*(C9)) -> 107.14286 | E9: Tractor + 4-bale Silage Wagon + Driver = $150/hr; 1-hour time
B11: Total Purchase (includes transport) | C11: =D3+D5 -> 405.71429
B12: Total Made | C12: =D7 -> 160
B13: Total Feed out | C13: =D9 -> 107.14286
B15: Bale weight (kg) | C15: 600
B16: Bales per tonne | C16: =1000/C15 -> 1.6666667
B17: DM (kg) per bale based on 11 MJ/ME | C17: 350
B18: Bales per silage wagon | C18: 4
B19: Machinery and labour cost (hr) | C19: 150
B20: Feed out time time (hr) | C20: 1

Sheet EFS & Debt
B2: Farm size
B3: Herd size | C3: Stocking rate | D3: Hectares | E3: EFS/ha | F3: EFS/cow | G3: Total Farm Scenario EFS | H3: Debt/ha | I3: Debt/cow | J3: Total Farm Scenario Debt
B4: ='Herd Distribution'!D8 -> 811.25 | C4: ='FCE calculation'!F11 -> 3.4796338 | D4: =B4/C4 -> 233.14235 | E4: ='Dairybase (North Cant) stats'!F7 -> 4772.8345 | F4: =E4/C4 -> 1371.6485 | G4: =D4*E4 -> 1112749.8 | H4: =C6/C7 -> 22022.02 | I4: =C6/C8 -> 7817.3164 | J4: =D4*H4 -> 5134265.3
B6: Total Dairy debt | C6: 36544000000 | D6: Ref Reserve bank | F6: https://www.rbnz.govt.nz/statistics/series/registered-banks/banks-assets-agriculture-loans-by-product
B7: Total Dairy area | C7: 1659430 | D7: Ref Dairy production stats
B8: Total Dairy cows | C8: 4674750 | D8: Ref Dairy production stats
B12: Canterbury median dairy farm sale price (ha) | C12: 49000 | D12: Farmers weekly - REINZ data
B13: Dairy cow price | C13: 2000 | D13: Canterbury livestock listings
B14: Debt:Asset ratio | C14: ='Dairybase (North Cant) stats'!AM7 -> 0.50508116 | D14: North Canterbury average for last 4-years
B15: Debt:Asset low range | C15: 0.4 | D15: BNZ + ANZ pers comm
B16: Debt:Asset high range | C16: 0.65 | D16: BNZ + ANZ pers comm
B17: Interest rate | C17: 0.0826 | D17: Feds
B18: Herd size | C18: 811
B19: Hectares | C19: 233
B20: Stocking rate | C20: =C18/C19 -> 3.4806867
E23: Average Farm Debt | H23: Low Range Farm Debt | K23: High Range Farm Debt
B24: EFS/ha | C24: EFS/cow | D24: Total Farm Scenario EFS | E24: Debt/ha | F24: Debt/cow | G24: Total Debt | H24: Debt/ha | I24: Debt/cow | J24: Total Debt | K24: Debt/ha | L24: Debt/cow | M24: Total Debt
B25: ='Dairybase (North Cant) stats'!F7 -> 4772.8345 | C25: =B25/C20 -> 1371.2336 | D25: =C19*B25 -> 1112070.4 | E25: =($C$12+($C$20*$C$13))*C14 -> 28265.035 | F25: =E25/C20 -> 8120.5342 | G25: =C19*E25 -> 6585753.2 | H25: =($C$12+($C$20*$C$13))*C15 -> 22384.549 | I25: =H25/C20 -> 6431.0727 | J25: =C19*H25 -> 5215600 | K25: =($C$12+($C$20*$C$13))*C16 -> 36374.893 | L25: =K25/C20 -> 10450.493 | M25: =C19*K25 -> 8475350
B27: Monthly interest payments | G27: =($C$17/12)*G25 -> 45331.935 | J27: =($C$17/12)*J25 -> 35900.713 | M27: =($C$17/12)*M25 -> 58338.659
B28: Total EFS | G28: =$B$25*$C$19 -> 1112070.4 | J28: =$B$25*$C$19 -> 1112070.4 | M28: =$B$25*$C$19 -> 1112070.4

Sheet FCE calculation Original
B2: From DairyNZ statistics
B3: Location | C3: Season | D3: Cow numbers | E3: Effective area (ha) | F3: Stocking rate (cows/ha) | G3: Total Milksolids (kg) | H3: MS/cow | I3: MS/ha | J3: Liveweight | K3: Feed demand/ cow (total kg) | L3: Feed demand/ ha (total kg) | M3: Feed demand (total kg) | N3: Feed demand (total kg) | O3: FCE (kg DM/ kg MS)
B5: Ref DairyNZ production statistics for North Canterbury + Dairybase data for feed demand - based on MPI method from
B6: North Canterbury | C6: =C13 -> 2022-23 | D6: 697292 | E6: 200849 | F6: =D6/E6 -> 3.4717225 | G6: 301907445 | H6: 434 | I6: 1503 | J6: 482 | K6: ='Dairybase (North Cant) stats'!AR3*1000 -> 4574.9701 | L6: =('Dairybase (North Cant) stats'!AF3+'Dairybase (North Cant) stats'!AG3+'Dairybase (North Cant) stats'!AH3+'Dairybase (North Cant) stats'!AI3)*1000 -> 18098.191 | M6: =D6*K6 -> 3.1900901e+09 | N6: =E6*L6 -> 3.6350036e+09 | O6: =M6/G6 -> 10.56645
B7: North Canterbury | C7: =C14 -> 2021-22 | D7: 720520 | E7: 206707 | F7: =D7/E7 -> 3.4857068 | G7: 302680670 | H7: 420 | I7: 1464 | J7: 486 | K7: ='Dairybase (North Cant) stats'!AR4*1000 -> 4671.717 | L7: =('Dairybase (North Cant) stats'!AF4+'Dairybase (North Cant) stats'!AG4+'Dairybase (North Cant) stats'!AH4+'Dairybase (North Cant) stats'!AI4)*1000 -> 18543.486 | M7: =D7*K7 -> 3.3660656e+09 | N7: =E7*L7 -> 3.8330684e+09 | O7: =M7/G7 -> 11.120847
B8: North Canterbury | C8: =C15 -> 2020-21 | D8: 723148 | E8: 207637 | F8: =D8/E8 -> 3.4827511 | G8: 315587803 | H8: 436 | I8: 1520 | J8: 458 | K8: ='Dairybase (North Cant) stats'!AR5*1000 -> 5062.0334 | L8: =('Dairybase (North Cant) stats'!AF5+'Dairybase (North Cant) stats'!AG5+'Dairybase (North Cant) stats'!AH5+'Dairybase (North Cant) stats'!AI5)*1000 -> 20151.107 | M8: =D8*K8 -> 3.6605994e+09 | N8: =E8*L8 -> 4.1841153e+09 | O8: =M8/G8 -> 11.599306
B9: North Canterbury | C9: =C16 -> 2019-20 | D9: 719289 | E9: 206790 | F9: =D9/E9 -> 3.4783549 | G9: 312626067 | H9: 435 | I9: 1512 | J9: 451 | K9: ='Dairybase (North Cant) stats'!AR6*1000 -> 5002.245 | L9: =('Dairybase (North Cant) stats'!AF6+'Dairybase (North Cant) stats'!AG6+'Dairybase (North Cant) stats'!AH6+'Dairybase (North Cant) stats'!AI6)*1000 -> 19899.451 | M9: =D9*K9 -> 3.5980598e+09 | N9: =E9*L9 -> 4.1150075e+09 | O9: =M9/G9 -> 11.509148
B10: Average | F10: =AVERAGE(F6:F9) -> 3.4796338 | O10: =AVERAGE(O6:O9) -> 11.198938
B12: Ref DairyNZ production statistics national + Dairybase data for feed demand
B13: All | C13: 2022-23 | D13: 4674750 | E13: 1659430 | F13: =D13/E13 -> 2.8170818 | G13: 1873020932 | H13: 393 | I13: 1125 | J13: 482 | K13: Could request these from Dairybase | M13: =D13*K13 -> #VALUE! | N13: =E13*L13 -> 0 | O13: =M13/G13 -> #VALUE!
B14: All | C14: 2021-22 | D14: 4842122 | E14: 1701380 | F14: =D14/E14 -> 2.8459968 | G14: 1867640344 | H14: 386 | I14: 1098 | J14: 486 | K14: Could request these from Dairybase | M14: =D14*K14 -> #VALUE! | N14: =E14*L14 -> 0 | O14: =M14/G14 -> #VALUE!
B15: All | C15: 2020-21 | D15: 4903733 | E15: 1713515 | F15: =D15/E15 -> 2.8617975 | G15: 1947533720 | H15: 397 | I15: 1137 | J15: 458 | K15: Could request these from Dairybase | M15: =D15*K15 -> #VALUE! | N15: =E15*L15 -> 0 | O15: =M15/G15 -> #VALUE!
B16: All | C16: 2019-20 | D16: 4921548 | E16: 1730374 | F16: =D16/E16 -> 2.8442106 | G16: 1895898580 | H16: 385 | I16: 1096 | J16: 451 | K16: Could request these from Dairybase | M16: =D16*K16 -> #VALUE! | N16: =E16*L16 -> 0 | O16: =M16/G16 -> #VALUE!
B17: Average | F17: =AVERAGE(F13:F16) -> 2.8422717 | O17: =AVERAGE(O13:O16) -> #VALUE!
